# LLM TEST REPORTER - SUMMARY MODE

FFFFFFFF.FFFFFFFFFFFFF...................F.Fs.Fx..F..F.F..F.F.F          [100%]SUITE: /Users/boyd/wip/reporters/python/pytest-reporter/tests/test_all_failing.py
FAILED TESTS:
- tests/test_all_failing.py > TestAllFailures > test_assertion_failure: AssertionError: Expected 10 but got 5
assert 5 == 10
- tests/test_all_failing.py > TestAllFailures > test_type_mismatch: TypeError: can only concatenate str (not "int") to str
- tests/test_all_failing.py > TestAllFailures > test_zero_division: ZeroDivisionError: division by zero
- tests/test_all_failing.py > TestAllFailures > test_index_out_of_bounds: IndexError: list index out of range
- tests/test_all_failing.py > TestAllFailures > test_key_not_found: KeyError: 'city'
- tests/test_all_failing.py > TestAllFailures > test_attribute_missing: AttributeError: 'Person' object has no attribute 'age'
- tests/test_all_failing.py > TestAllFailures > test_import_failure: ModuleNotFoundError: No module named 'non_existent_module'
- tests/test_all_failing.py > TestAllFailures > test_value_conversion_error: ValueError: invalid literal for int() with base 10: 'not a number'
- tests/test_all_failing.py > TestAllFailures > test_name_undefined: NameError: name 'undefined_variable' is not defined
- tests/test_all_failing.py > TestComplexFailures > test_nested_assertion_failure: AssertionError: assert {'user': {'na...e': 'light'}}} == {'user': {'na...me': 'dark'}}}
  
  Differi...
- tests/test_all_failing.py > TestComplexFailures > test_list_comparison_failure: assert [1, 2, 30, 40, 5] == [1, 2, 3, 4, 5]
  
  At index 2 diff: 30 != 3
  Use -v to get more diff
- tests/test_all_failing.py > TestComplexFailures > test_custom_exception: test_all_failing.TestComplexFailures.test_custom_exception.<locals>.CustomError: Operation failed du...
- tests/test_all_failing.py > TestComplexFailures > test_multiple_assertions_fail: assert 5 > 10
- tests/test_all_failing.py > test_parametrized_all_fail[1-2]: assert 1 == 2
- tests/test_all_failing.py > test_parametrized_all_fail[2-3]: assert 2 == 3
- tests/test_all_failing.py > test_parametrized_all_fail[3-5]: assert 3 == 5
- tests/test_all_failing.py > test_parametrized_all_fail[4-7]: assert 4 == 7
- tests/test_all_failing.py > TestAsyncFailures > test_async_assertion_failure: assert 42 == 100
- tests/test_all_failing.py > TestAsyncFailures > test_async_exception: RuntimeError: Async operation failed
- tests/test_all_failing.py > test_fixture_usage_failure: assert 1 == 2
- tests/test_all_failing.py > test_permission_denied: FileNotFoundError: [Errno 2] No such file or directory: '/root/test.txt'

SUITE: /Users/boyd/wip/reporters/python/pytest-reporter/tests/test_mixed_results.py
FAILED TESTS:
- tests/test_mixed_results.py > TestMixedResults > test_failing_equality: assert 4 == 5
- tests/test_mixed_results.py > TestMixedResults > test_failing_type_error: TypeError: can only concatenate str (not "int") to str
- tests/test_mixed_results.py > TestMixedResults > test_failing_key_error: KeyError: 'city'
- tests/test_mixed_results.py > TestAsyncOperations > test_async_timeout: TimeoutError
- tests/test_mixed_results.py > TestParametrizedMixed > test_square_numbers[4-15]: assert (4 ** 2) == 15
- tests/test_mixed_results.py > TestParametrizedMixed > test_square_numbers[6-35]: assert (6 ** 2) == 35
- tests/test_mixed_results.py > TestParametrizedMixed > test_string_length[python-7]: AssertionError: assert 6 == 7
 +  where 6 = len('python')
- tests/test_mixed_results.py > TestParametrizedMixed > test_string_length[test-5]: AssertionError: assert 4 == 5
 +  where 4 = len('test')
- tests/test_mixed_results.py > test_value_error_handling: ValueError: invalid literal for int() with base 10: 'not a number'

---
## SUMMARY
- PASSED SUITES: 1
- FAILED SUITES: 2
- TOTAL TESTS: 62 (31 passed, 30 failed, 1 skipped)
- DURATION: 10.21s
- EXIT CODE: 1

=================================== FAILURES ===================================
____________________ TestAllFailures.test_assertion_failure ____________________
tests/test_all_failing.py:15: in test_assertion_failure
    assert actual == expected, f"Expected {expected} but got {actual}"
E   AssertionError: Expected 10 but got 5
E   assert 5 == 10
______________________ TestAllFailures.test_type_mismatch ______________________
tests/test_all_failing.py:20: in test_type_mismatch
    result = "string" + 123
             ^^^^^^^^^^^^^^
E   TypeError: can only concatenate str (not "int") to str
______________________ TestAllFailures.test_zero_division ______________________
tests/test_all_failing.py:27: in test_zero_division
    result = numerator / denominator
             ^^^^^^^^^^^^^^^^^^^^^^^
E   ZeroDivisionError: division by zero
___________________ TestAllFailures.test_index_out_of_bounds ___________________
tests/test_all_failing.py:34: in test_index_out_of_bounds
    value = items[10]
            ^^^^^^^^^
E   IndexError: list index out of range
______________________ TestAllFailures.test_key_not_found ______________________
tests/test_all_failing.py:41: in test_key_not_found
    city = data["city"]
           ^^^^^^^^^^^^
E   KeyError: 'city'
____________________ TestAllFailures.test_attribute_missing ____________________
tests/test_all_failing.py:52: in test_attribute_missing
    age = person.age
          ^^^^^^^^^^
E   AttributeError: 'Person' object has no attribute 'age'
_____________________ TestAllFailures.test_import_failure ______________________
tests/test_all_failing.py:57: in test_import_failure
    import non_existent_module
E   ModuleNotFoundError: No module named 'non_existent_module'
_________________ TestAllFailures.test_value_conversion_error __________________
tests/test_all_failing.py:63: in test_value_conversion_error
    number = int(text)
             ^^^^^^^^^
E   ValueError: invalid literal for int() with base 10: 'not a number'
_____________________ TestAllFailures.test_name_undefined ______________________
tests/test_all_failing.py:75: in test_name_undefined
    result = undefined_variable * 2
             ^^^^^^^^^^^^^^^^^^
E   NameError: name 'undefined_variable' is not defined
______________ TestComplexFailures.test_nested_assertion_failure _______________
tests/test_all_failing.py:104: in test_nested_assertion_failure
    assert actual == expected
E   AssertionError: assert {'user': {'na...e': 'light'}}} == {'user': {'na...me': 'dark'}}}
E     
E     Differing items:
E     {'user': {'name': 'John', 'settings': {'notifications': False, 'theme': 'light'}}} != {'user': {'name': 'John', 'settings': {'notifications': True, 'theme': 'dark'}}}
E     Use -v to get more diff
_______________ TestComplexFailures.test_list_comparison_failure _______________
tests/test_all_failing.py:110: in test_list_comparison_failure
    assert actual == expected
E   assert [1, 2, 30, 40, 5] == [1, 2, 3, 4, 5]
E     
E     At index 2 diff: 30 != 3
E     Use -v to get more diff
__________________ TestComplexFailures.test_custom_exception ___________________
tests/test_all_failing.py:120: in test_custom_exception
    result = risky_operation()
             ^^^^^^^^^^^^^^^^^
tests/test_all_failing.py:118: in risky_operation
    raise CustomError("Operation failed due to custom reason")
E   test_all_failing.TestComplexFailures.test_custom_exception.<locals>.CustomError: Operation failed due to custom reason
______________ TestComplexFailures.test_multiple_assertions_fail _______________
tests/test_all_failing.py:126: in test_multiple_assertions_fail
    assert value > 10  # This fails
    ^^^^^^^^^^^^^^^^^
E   assert 5 > 10
_______________________ test_parametrized_all_fail[1-2] ________________________
tests/test_all_failing.py:139: in test_parametrized_all_fail
    assert input == expected
E   assert 1 == 2
_______________________ test_parametrized_all_fail[2-3] ________________________
tests/test_all_failing.py:139: in test_parametrized_all_fail
    assert input == expected
E   assert 2 == 3
_______________________ test_parametrized_all_fail[3-5] ________________________
tests/test_all_failing.py:139: in test_parametrized_all_fail
    assert input == expected
E   assert 3 == 5
_______________________ test_parametrized_all_fail[4-7] ________________________
tests/test_all_failing.py:139: in test_parametrized_all_fail
    assert input == expected
E   assert 4 == 7
________________ TestAsyncFailures.test_async_assertion_failure ________________
tests/test_all_failing.py:152: in test_async_assertion_failure
    assert result == 100
E   assert 42 == 100
____________________ TestAsyncFailures.test_async_exception ____________________
tests/test_all_failing.py:160: in test_async_exception
    result = await failing_operation()
             ^^^^^^^^^^^^^^^^^^^^^^^^^
tests/test_all_failing.py:158: in failing_operation
    raise RuntimeError("Async operation failed")
E   RuntimeError: Async operation failed
__________________________ test_fixture_usage_failure __________________________
tests/test_all_failing.py:177: in test_fixture_usage_failure
    assert data["count"] == 2
E   assert 1 == 2
____________________________ test_permission_denied ____________________________
tests/test_all_failing.py:183: in test_permission_denied
    with open("/root/test.txt", "w") as f:
         ^^^^^^^^^^^^^^^^^^^^^^^^^^^
E   FileNotFoundError: [Errno 2] No such file or directory: '/root/test.txt'
____________________ TestMixedResults.test_failing_equality ____________________
tests/test_mixed_results.py:20: in test_failing_equality
    assert result == 5  # This will fail
    ^^^^^^^^^^^^^^^^^^
E   assert 4 == 5
___________________ TestMixedResults.test_failing_type_error ___________________
tests/test_mixed_results.py:31: in test_failing_type_error
    result = "string" + 5
             ^^^^^^^^^^^^
E   TypeError: can only concatenate str (not "int") to str
___________________ TestMixedResults.test_failing_key_error ____________________
tests/test_mixed_results.py:50: in test_failing_key_error
    value = data["city"]
            ^^^^^^^^^^^^
E   KeyError: 'city'
____________________ TestAsyncOperations.test_async_timeout ____________________
tests/test_mixed_results.py:82: in slow_operation
    await asyncio.sleep(10)  # This will timeout
    ^^^^^^^^^^^^^^^^^^^^^^^
/opt/homebrew/Cellar/python@3.13/3.13.3_1/Frameworks/Python.framework/Versions/3.13/lib/python3.13/asyncio/tasks.py:718: in sleep
    return await future
           ^^^^^^^^^^^^
E   asyncio.exceptions.CancelledError

The above exception was the direct cause of the following exception:
tests/test_mixed_results.py:86: in test_async_timeout
    result = await asyncio.wait_for(slow_operation(), timeout=0.1)
             ^^^^^^^^^^^^^^^^^^^^^^^^^^^^^^^^^^^^^^^^^^^^^^^^^^^^^
/opt/homebrew/Cellar/python@3.13/3.13.3_1/Frameworks/Python.framework/Versions/3.13/lib/python3.13/asyncio/tasks.py:506: in wait_for
    async with timeouts.timeout(timeout):
               ^^^^^^^^^^^^^^^^^^^^^^^^^
/opt/homebrew/Cellar/python@3.13/3.13.3_1/Frameworks/Python.framework/Versions/3.13/lib/python3.13/asyncio/timeouts.py:116: in __aexit__
    raise TimeoutError from exc_val
E   TimeoutError
_______________ TestParametrizedMixed.test_square_numbers[4-15] ________________
tests/test_mixed_results.py:102: in test_square_numbers
    assert value ** 2 == expected
E   assert (4 ** 2) == 15
_______________ TestParametrizedMixed.test_square_numbers[6-35] ________________
tests/test_mixed_results.py:102: in test_square_numbers
    assert value ** 2 == expected
E   assert (6 ** 2) == 35
______________ TestParametrizedMixed.test_string_length[python-7] ______________
tests/test_mixed_results.py:113: in test_string_length
    assert len(text) == length
E   AssertionError: assert 6 == 7
E    +  where 6 = len('python')
_______________ TestParametrizedMixed.test_string_length[test-5] _______________
tests/test_mixed_results.py:113: in test_string_length
    assert len(text) == length
E   AssertionError: assert 4 == 5
E    +  where 4 = len('test')
__________________________ test_value_error_handling ___________________________
tests/test_mixed_results.py:137: in test_value_error_handling
    result = parse_number("not a number")
             ^^^^^^^^^^^^^^^^^^^^^^^^^^^^
tests/test_mixed_results.py:134: in parse_number
    return int(text)
           ^^^^^^^^^
E   ValueError: invalid literal for int() with base 10: 'not a number'
Traceback (most recent call last):
  File "/Users/boyd/wip/reporters/python/.venv/bin/pytest", line 8, in <module>
    sys.exit(console_main())
             ~~~~~~~~~~~~^^
  File "/Users/boyd/wip/reporters/python/.venv/lib/python3.13/site-packages/_pytest/config/__init__.py", line 201, in console_main
    code = main()
  File "/Users/boyd/wip/reporters/python/.venv/lib/python3.13/site-packages/_pytest/config/__init__.py", line 175, in main
    ret: ExitCode | int = config.hook.pytest_cmdline_main(config=config)
                          ~~~~~~~~~~~~~~~~~~~~~~~~~~~~~~~^^^^^^^^^^^^^^^
  File "/Users/boyd/wip/reporters/python/.venv/lib/python3.13/site-packages/pluggy/_hooks.py", line 512, in __call__
    return self._hookexec(self.name, self._hookimpls.copy(), kwargs, firstresult)
           ~~~~~~~~~~~~~~^^^^^^^^^^^^^^^^^^^^^^^^^^^^^^^^^^^^^^^^^^^^^^^^^^^^^^^^
  File "/Users/boyd/wip/reporters/python/.venv/lib/python3.13/site-packages/pluggy/_manager.py", line 120, in _hookexec
    return self._inner_hookexec(hook_name, methods, kwargs, firstresult)
           ~~~~~~~~~~~~~~~~~~~~^^^^^^^^^^^^^^^^^^^^^^^^^^^^^^^^^^^^^^^^^
  File "/Users/boyd/wip/reporters/python/.venv/lib/python3.13/site-packages/pluggy/_callers.py", line 167, in _multicall
    raise exception
  File "/Users/boyd/wip/reporters/python/.venv/lib/python3.13/site-packages/pluggy/_callers.py", line 121, in _multicall
    res = hook_impl.function(*args)
  File "/Users/boyd/wip/reporters/python/.venv/lib/python3.13/site-packages/_pytest/main.py", line 336, in pytest_cmdline_main
    return wrap_session(config, _main)
  File "/Users/boyd/wip/reporters/python/.venv/lib/python3.13/site-packages/_pytest/main.py", line 324, in wrap_session
    config.hook.pytest_sessionfinish(
    ~~~~~~~~~~~~~~~~~~~~~~~~~~~~~~~~^
        session=session, exitstatus=session.exitstatus
        ^^^^^^^^^^^^^^^^^^^^^^^^^^^^^^^^^^^^^^^^^^^^^^
    )
    ^
  File "/Users/boyd/wip/reporters/python/.venv/lib/python3.13/site-packages/pluggy/_hooks.py", line 512, in __call__
    return self._hookexec(self.name, self._hookimpls.copy(), kwargs, firstresult)
           ~~~~~~~~~~~~~~^^^^^^^^^^^^^^^^^^^^^^^^^^^^^^^^^^^^^^^^^^^^^^^^^^^^^^^^
  File "/Users/boyd/wip/reporters/python/.venv/lib/python3.13/site-packages/pluggy/_manager.py", line 120, in _hookexec
    return self._inner_hookexec(hook_name, methods, kwargs, firstresult)
           ~~~~~~~~~~~~~~~~~~~~^^^^^^^^^^^^^^^^^^^^^^^^^^^^^^^^^^^^^^^^^
  File "/Users/boyd/wip/reporters/python/.venv/lib/python3.13/site-packages/pluggy/_callers.py", line 167, in _multicall
    raise exception
  File "/Users/boyd/wip/reporters/python/.venv/lib/python3.13/site-packages/pluggy/_callers.py", line 139, in _multicall
    teardown.throw(exception)
    ~~~~~~~~~~~~~~^^^^^^^^^^^
  File "/Users/boyd/wip/reporters/python/.venv/lib/python3.13/site-packages/_pytest/logging.py", line 873, in pytest_sessionfinish
    return (yield)
            ^^^^^
  File "/Users/boyd/wip/reporters/python/.venv/lib/python3.13/site-packages/pluggy/_callers.py", line 152, in _multicall
    teardown.send(result)
    ~~~~~~~~~~~~~^^^^^^^^
  File "/Users/boyd/wip/reporters/python/.venv/lib/python3.13/site-packages/_pytest/terminal.py", line 944, in pytest_sessionfinish
    self.config.hook.pytest_terminal_summary(
    ~~~~~~~~~~~~~~~~~~~~~~~~~~~~~~~~~~~~~~~~^
        terminalreporter=self, exitstatus=exitstatus, config=self.config
        ^^^^^^^^^^^^^^^^^^^^^^^^^^^^^^^^^^^^^^^^^^^^^^^^^^^^^^^^^^^^^^^^
    )
    ^
  File "/Users/boyd/wip/reporters/python/.venv/lib/python3.13/site-packages/pluggy/_hooks.py", line 512, in __call__
    return self._hookexec(self.name, self._hookimpls.copy(), kwargs, firstresult)
           ~~~~~~~~~~~~~~^^^^^^^^^^^^^^^^^^^^^^^^^^^^^^^^^^^^^^^^^^^^^^^^^^^^^^^^
  File "/Users/boyd/wip/reporters/python/.venv/lib/python3.13/site-packages/pluggy/_manager.py", line 120, in _hookexec
    return self._inner_hookexec(hook_name, methods, kwargs, firstresult)
           ~~~~~~~~~~~~~~~~~~~~^^^^^^^^^^^^^^^^^^^^^^^^^^^^^^^^^^^^^^^^^
  File "/Users/boyd/wip/reporters/python/.venv/lib/python3.13/site-packages/pluggy/_callers.py", line 167, in _multicall
    raise exception
  File "/Users/boyd/wip/reporters/python/.venv/lib/python3.13/site-packages/pluggy/_callers.py", line 139, in _multicall
    teardown.throw(exception)
    ~~~~~~~~~~~~~~^^^^^^^^^^^
  File "/Users/boyd/wip/reporters/python/.venv/lib/python3.13/site-packages/_pytest/terminal.py", line 966, in pytest_terminal_summary
    return (yield)
            ^^^^^
  File "/Users/boyd/wip/reporters/python/.venv/lib/python3.13/site-packages/pluggy/_callers.py", line 139, in _multicall
    teardown.throw(exception)
    ~~~~~~~~~~~~~~^^^^^^^^^^^
  File "/Users/boyd/wip/reporters/python/.venv/lib/python3.13/site-packages/_pytest/warnings.py", line 110, in pytest_terminal_summary
    return (yield)
            ^^^^^
  File "/Users/boyd/wip/reporters/python/.venv/lib/python3.13/site-packages/pluggy/_callers.py", line 121, in _multicall
    res = hook_impl.function(*args)
  File "/Users/boyd/wip/reporters/python/pytest-reporter/src/llm_pytest_reporter/plugin.py", line 199, in pytest_terminal_summary
    terminalreporter._durations.clear()
    ^^^^^^^^^^^^^^^^^^^^^^^^^^^
AttributeError: 'TerminalReporter' object has no attribute '_durations'
