# LLM TEST REPORTER - SUMMARY MODE

SUITE: /Users/boyd/wip/reporters/python/pytest-reporter/tests/test_all_failing.py
FAILED TESTS:
- tests/test_all_failing.py > TestAllFailures > test_assertion_failure: AssertionError
- tests/test_all_failing.py > TestAllFailures > test_type_mismatch: TypeError: can only concatenate str (not "int") to str
- tests/test_all_failing.py > TestAllFailures > test_zero_division: ZeroDivisionError: division by zero
- tests/test_all_failing.py > TestAllFailures > test_index_out_of_bounds: IndexError: list index out of range
- tests/test_all_failing.py > TestAllFailures > test_key_not_found: KeyError: 'city'
- tests/test_all_failing.py > TestAllFailures > test_attribute_missing: AttributeError: 'Person' object has no attribute 'age'
- tests/test_all_failing.py > TestAllFailures > test_import_failure: ModuleNotFoundError: No module named 'non_existent_module'
- tests/test_all_failing.py > TestAllFailures > test_value_conversion_error: ValueError: invalid literal for int() with base 10: 'not a number'
- tests/test_all_failing.py > TestAllFailures > test_name_undefined: NameError: name 'undefined_variable' is not defined
- tests/test_all_failing.py > TestComplexFailures > test_nested_assertion_failure: AssertionError
- tests/test_all_failing.py > TestComplexFailures > test_list_comparison_failure: AssertionError
- tests/test_all_failing.py > TestComplexFailures > test_custom_exception: test_all_failing.TestComplexFailures.test_custom_exception.<locals>.CustomError: Operation failed du...
- tests/test_all_failing.py > TestComplexFailures > test_multiple_assertions_fail: AssertionError
- tests/test_all_failing.py > test_parametrized_all_fail[1-2]: AssertionError
- tests/test_all_failing.py > test_parametrized_all_fail[2-3]: AssertionError
- tests/test_all_failing.py > test_parametrized_all_fail[3-5]: AssertionError
- tests/test_all_failing.py > test_parametrized_all_fail[4-7]: AssertionError
- tests/test_all_failing.py > TestAsyncFailures > test_async_assertion_failure: AssertionError
- tests/test_all_failing.py > TestAsyncFailures > test_async_exception: RuntimeError: Async operation failed
- tests/test_all_failing.py > test_fixture_usage_failure: AssertionError
- tests/test_all_failing.py > test_permission_denied: FileNotFoundError: [Errno 2] No such file or directory: '/root/test.txt'

SUITE: /Users/boyd/wip/reporters/python/pytest-reporter/tests/test_mixed_results.py
FAILED TESTS:
- tests/test_mixed_results.py > TestMixedResults > test_failing_equality: AssertionError
- tests/test_mixed_results.py > TestMixedResults > test_failing_type_error: TypeError: can only concatenate str (not "int") to str
- tests/test_mixed_results.py > TestMixedResults > test_failing_key_error: KeyError: 'city'
- tests/test_mixed_results.py > TestAsyncOperations > test_async_timeout: TimeoutError
- tests/test_mixed_results.py > TestParametrizedMixed > test_square_numbers[4-15]: AssertionError
- tests/test_mixed_results.py > TestParametrizedMixed > test_square_numbers[6-35]: AssertionError
- tests/test_mixed_results.py > TestParametrizedMixed > test_string_length[python-7]: AssertionError
- tests/test_mixed_results.py > TestParametrizedMixed > test_string_length[test-5]: AssertionError
- tests/test_mixed_results.py > test_value_error_handling: ValueError: invalid literal for int() with base 10: 'not a number'

---
## SUMMARY
- PASSED SUITES: 1
- FAILED SUITES: 2
- TOTAL TESTS: 62 (31 passed, 30 failed, 1 skipped)
- DURATION: 10.62s
- EXIT CODE: 1
