INTERNALERROR> Traceback (most recent call last):
INTERNALERROR>   File "/Users/boyd/wip/reporters/python/.venv/lib/python3.13/site-packages/_pytest/main.py", line 285, in wrap_session
INTERNALERROR>     config._do_configure()
INTERNALERROR>     ~~~~~~~~~~~~~~~~~~~~^^
INTERNALERROR>   File "/Users/boyd/wip/reporters/python/.venv/lib/python3.13/site-packages/_pytest/config/__init__.py", line 1119, in _do_configure
INTERNALERROR>     self.hook.pytest_configure.call_historic(kwargs=dict(config=self))
INTERNALERROR>     ~~~~~~~~~~~~~~~~~~~~~~~~~~~~~~~~~~~~~~~~^^^^^^^^^^^^^^^^^^^^^^^^^^
INTERNALERROR>   File "/Users/boyd/wip/reporters/python/.venv/lib/python3.13/site-packages/pluggy/_hooks.py", line 534, in call_historic
INTERNALERROR>     res = self._hookexec(self.name, self._hookimpls.copy(), kwargs, False)
INTERNALERROR>   File "/Users/boyd/wip/reporters/python/.venv/lib/python3.13/site-packages/pluggy/_manager.py", line 120, in _hookexec
INTERNALERROR>     return self._inner_hookexec(hook_name, methods, kwargs, firstresult)
INTERNALERROR>            ~~~~~~~~~~~~~~~~~~~~^^^^^^^^^^^^^^^^^^^^^^^^^^^^^^^^^^^^^^^^^
INTERNALERROR>   File "/Users/boyd/wip/reporters/python/.venv/lib/python3.13/site-packages/pluggy/_callers.py", line 167, in _multicall
INTERNALERROR>     raise exception
INTERNALERROR>   File "/Users/boyd/wip/reporters/python/.venv/lib/python3.13/site-packages/pluggy/_callers.py", line 121, in _multicall
INTERNALERROR>     res = hook_impl.function(*args)
INTERNALERROR>   File "/Users/boyd/wip/reporters/python/pytest-reporter/src/llm_pytest_reporter/plugin.py", line 219, in pytest_configure
INTERNALERROR>     config.pluginmanager.register(reporter, "llm_reporter")
INTERNALERROR>     ~~~~~~~~~~~~~~~~~~~~~~~~~~~~~^^^^^^^^^^^^^^^^^^^^^^^^^^
INTERNALERROR>   File "/Users/boyd/wip/reporters/python/.venv/lib/python3.13/site-packages/_pytest/config/__init__.py", line 503, in register
INTERNALERROR>     plugin_name = super().register(plugin, name)
INTERNALERROR>   File "/Users/boyd/wip/reporters/python/.venv/lib/python3.13/site-packages/pluggy/_manager.py", line 140, in register
INTERNALERROR>     raise ValueError(
INTERNALERROR>     ...<2 lines>...
INTERNALERROR>     )
INTERNALERROR> ValueError: Plugin name already registered: llm_reporter=<llm_pytest_reporter.plugin.LLMReporter object at 0x102844440>
INTERNALERROR> {'4330525360': <_pytest.config.PytestPluginManager object at 0x1021e92b0>, 'pytestconfig': <_pytest.config.Config object at 0x1021eb770>, 'mark': <module '_pytest.mark' from '/Users/boyd/wip/reporters/python/.venv/lib/python3.13/site-packages/_pytest/mark/__init__.py'>, 'main': <module '_pytest.main' from '/Users/boyd/wip/reporters/python/.venv/lib/python3.13/site-packages/_pytest/main.py'>, 'runner': <module '_pytest.runner' from '/Users/boyd/wip/reporters/python/.venv/lib/python3.13/site-packages/_pytest/runner.py'>, 'fixtures': <module '_pytest.fixtures' from '/Users/boyd/wip/reporters/python/.venv/lib/python3.13/site-packages/_pytest/fixtures.py'>, 'helpconfig': <module '_pytest.helpconfig' from '/Users/boyd/wip/reporters/python/.venv/lib/python3.13/site-packages/_pytest/helpconfig.py'>, 'python': <module '_pytest.python' from '/Users/boyd/wip/reporters/python/.venv/lib/python3.13/site-packages/_pytest/python.py'>, 'terminal': <module '_pytest.terminal' from '/Users/boyd/wip/reporters/python/.venv/lib/python3.13/site-packages/_pytest/terminal.py'>, 'debugging': <module '_pytest.debugging' from '/Users/boyd/wip/reporters/python/.venv/lib/python3.13/site-packages/_pytest/debugging.py'>, 'unittest': <module '_pytest.unittest' from '/Users/boyd/wip/reporters/python/.venv/lib/python3.13/site-packages/_pytest/unittest.py'>, 'capture': <module '_pytest.capture' from '/Users/boyd/wip/reporters/python/.venv/lib/python3.13/site-packages/_pytest/capture.py'>, 'skipping': <module '_pytest.skipping' from '/Users/boyd/wip/reporters/python/.venv/lib/python3.13/site-packages/_pytest/skipping.py'>, 'legacypath': <module '_pytest.legacypath' from '/Users/boyd/wip/reporters/python/.venv/lib/python3.13/site-packages/_pytest/legacypath.py'>, 'tmpdir': <module '_pytest.tmpdir' from '/Users/boyd/wip/reporters/python/.venv/lib/python3.13/site-packages/_pytest/tmpdir.py'>, 'monkeypatch': <module '_pytest.monkeypatch' from '/Users/boyd/wip/reporters/python/.venv/lib/python3.13/site-packages/_pytest/monkeypatch.py'>, 'recwarn': <module '_pytest.recwarn' from '/Users/boyd/wip/reporters/python/.venv/lib/python3.13/site-packages/_pytest/recwarn.py'>, 'pastebin': <module '_pytest.pastebin' from '/Users/boyd/wip/reporters/python/.venv/lib/python3.13/site-packages/_pytest/pastebin.py'>, 'assertion': <module '_pytest.assertion' from '/Users/boyd/wip/reporters/python/.venv/lib/python3.13/site-packages/_pytest/assertion/__init__.py'>, 'junitxml': <module '_pytest.junitxml' from '/Users/boyd/wip/reporters/python/.venv/lib/python3.13/site-packages/_pytest/junitxml.py'>, 'doctest': <module '_pytest.doctest' from '/Users/boyd/wip/reporters/python/.venv/lib/python3.13/site-packages/_pytest/doctest.py'>, 'cacheprovider': <module '_pytest.cacheprovider' from '/Users/boyd/wip/reporters/python/.venv/lib/python3.13/site-packages/_pytest/cacheprovider.py'>, 'freeze_support': <module '_pytest.freeze_support' from '/Users/boyd/wip/reporters/python/.venv/lib/python3.13/site-packages/_pytest/freeze_support.py'>, 'setuponly': <module '_pytest.setuponly' from '/Users/boyd/wip/reporters/python/.venv/lib/python3.13/site-packages/_pytest/setuponly.py'>, 'setupplan': <module '_pytest.setupplan' from '/Users/boyd/wip/reporters/python/.venv/lib/python3.13/site-packages/_pytest/setupplan.py'>, 'stepwise': <module '_pytest.stepwise' from '/Users/boyd/wip/reporters/python/.venv/lib/python3.13/site-packages/_pytest/stepwise.py'>, 'unraisableexception': <module '_pytest.unraisableexception' from '/Users/boyd/wip/reporters/python/.venv/lib/python3.13/site-packages/_pytest/unraisableexception.py'>, 'threadexception': <module '_pytest.threadexception' from '/Users/boyd/wip/reporters/python/.venv/lib/python3.13/site-packages/_pytest/threadexception.py'>, 'warnings': <module '_pytest.warnings' from '/Users/boyd/wip/reporters/python/.venv/lib/python3.13/site-packages/_pytest/warnings.py'>, 'logging': <module '_pytest.logging' from '/Users/boyd/wip/reporters/python/.venv/lib/python3.13/site-packages/_pytest/logging.py'>, 'reports': <module '_pytest.reports' from '/Users/boyd/wip/reporters/python/.venv/lib/python3.13/site-packages/_pytest/reports.py'>, 'faulthandler': <module '_pytest.faulthandler' from '/Users/boyd/wip/reporters/python/.venv/lib/python3.13/site-packages/_pytest/faulthandler.py'>, 'llm_reporter': <module 'llm_pytest_reporter.plugin' from '/Users/boyd/wip/reporters/python/pytest-reporter/src/llm_pytest_reporter/plugin.py'>, 'asyncio': <module 'pytest_asyncio.plugin' from '/Users/boyd/wip/reporters/python/.venv/lib/python3.13/site-packages/pytest_asyncio/plugin.py'>, 'capturemanager': <CaptureManager _method='fd' _global_capturing=<MultiCapture out=<FDCapture 1 oldfd=5 _state='suspended' tmpfile=<EncodedFile name="<_io.FileIO name=6 mode='rb+' closefd=True>" mode='r+' encoding='utf-8'>> err=<FDCapture 2 oldfd=7 _state='suspended' tmpfile=<EncodedFile name="<_io.FileIO name=8 mode='rb+' closefd=True>" mode='r+' encoding='utf-8'>> in_=<FDCapture 0 oldfd=3 _state='started' tmpfile=<_io.TextIOWrapper name='/dev/null' mode='r' encoding='utf-8'>> _state='suspended' _in_suspended=False> _capture_fixture=None>, 'session': <Session  exitstatus=<ExitCode.OK: 0> testsfailed=0 testscollected=0>, 'lfplugin': <_pytest.cacheprovider.LFPlugin object at 0x10247fa10>, 'nfplugin': <_pytest.cacheprovider.NFPlugin object at 0x102844590>}
