{
  "files": {
    "typescript_mocha_summary.txt": {
      "valid": true,
      "errors": [],
      "warnings": [],
      "sections": {
        "header": "# LLM TEST REPORTER - SUMMARY MODE\n",
        "suites": "SUITE: /Users/boyd/wip/reporters/typescript/mocha-reporter/tests/all-failing.test.js\nFAILED TESTS:\n- All Failing Tests > Test 1 - Should fail: Expected values to be strictly equal:\n- All Failing Tests > Test 2 - Should fail: Cannot read properties of null (reading 'length')\n- All Failing Tests > Test 3 - Should fail: Timeout of 500ms exceeded. For async tests and hooks, ensure \"done()\" is call...\n\n---\nSUITE: /Users/boyd/wip/reporters/typescript/mocha-reporter/tests/mixed-results.test.js\nFAILED TESTS:\n- Mixed Results > Test 2 - Should fail: Expected 5 but got 4\n- Mixed Results > Test 4 - Should fail: Cannot read properties of undefined (reading 'property')\n\n---",
        "summary": "## SUMMARY\n- PASSED SUITES: 0\n- FAILED SUITES: 2\n- TOTAL TESTS: 8 (2 passed, 5 failed)\n- DURATION: 0.51s\n- EXIT CODE: 1"
      }
    },
    "typescript_vitest_detailed.txt": {
      "valid": true,
      "errors": [],
      "warnings": [],
      "sections": {
        "header": "# LLM TEST REPORTER - DETAILED MODE\n",
        "test_failure_#1": "## TEST FAILURE #1",
        "suites": "SUITE: Mixed Results\nTEST: Test 4 - Should fail\nFILE: /Users/boyd/wip/reporters/typescript/vitest-reporter/tests/mixed-results.test.ts:18\nTYPE: Type Error\n\nCODE CONTEXT:\n  16 |   test('Test 4 - Should fail', () => {\n  17 |     const obj: any = undefined;\n> 18 |     expect(obj.property).toBe('value'); // Will fail: Cannot read property of undefined\n     |                ^\n  19 |   });\n  20 | \n\nFAILURE REASON: Type error: Cannot read properties of undefined (reading 'property')\nFIX HINT: Check variable types and ensure proper initialization\n\n---",
        "test_failure_#2": "## TEST FAILURE #2",
        "test_failure_#3": "## TEST FAILURE #3",
        "test_failure_#4": "## TEST FAILURE #4",
        "test_failure_#5": "## TEST FAILURE #5",
        "error_patterns_detected": "## ERROR PATTERNS DETECTED\n- 5 tests failed due to Multiple failures in tests module\n- 2 tests failed due to Multiple assertion failures\n- 2 tests failed due to Multiple type-related errors\n\n---",
        "summary": "## SUMMARY\n- TOTAL TESTS: 7 (2 passed, 5 failed)\n- FAILURE RATE: 71.43%\n- DURATION: 0.69s\n- EXIT CODE: 1"
      }
    },
    "typescript_playwright_summary.txt": {
      "valid": true,
      "errors": [],
      "warnings": [],
      "sections": {
        "header": "# LLM TEST REPORTER - SUMMARY MODE\n",
        "suites": "SUITE: /Users/boyd/wip/reporters/typescript/playwright-reporter/tests/all-failing.spec.ts\nFAILED TESTS:\n- chromium > all-failing.spec.ts > All Failing Tests > Test 1 - Should fail > chromium: expect(received).toBe(expected...\n- chromium > all-failing.spec.ts > All Failing Tests > Test 2 - Should fail > chromium: TypeError: Cannot read properties of null (reading 'length')\n- chromium > all-failing.spec.ts > All Failing Tests > Test 3 - Should fail > chromium: Test timeout of 500ms exceeded.\n\n---\nSUITE: /Users/boyd/wip/reporters/typescript/playwright-reporter/tests/mixed-results.spec.ts\nFAILED TESTS:\n- chromium > mixed-results.spec.ts > Mixed Results > Test 2 - Should fail > chromium: expect(received).toBe(expected...\n- chromium > mixed-results.spec.ts > Mixed Results > Test 4 - Should fail > chromium: TypeError: Cannot read properties of undefined (reading 'property')\n\n---",
        "summary": "## SUMMARY\n- PASSED SUITES: 0\n- FAILED SUITES: 2\n- TOTAL TESTS: 11 (2 passed, 5 failed)\n- DURATION: 1.78s\n- EXIT CODE: 1"
      }
    },
    "python_unittest_summary.txt": {
      "valid": false,
      "errors": [
        "Missing or invalid header"
      ],
      "warnings": [],
      "sections": {
        "header": "---",
        "summary": "## SUMMARY\n- PASSED SUITES: 0\n- FAILED SUITES: 0\n- TOTAL TESTS: 0\n- DURATION: 0.00s\n- EXIT CODE: 0\nRan 0 tests in 0.000s\n\nNO TESTS RAN\n"
      }
    },
    "typescript_playwright_detailed.txt": {
      "valid": true,
      "errors": [],
      "warnings": [],
      "sections": {
        "header": "# LLM TEST REPORTER - DETAILED MODE\n",
        "test_failure_#1": "## TEST FAILURE #1",
        "suites": "SUITE: chromium > mixed-results.spec.ts > Mixed Results\nTEST: chromium > mixed-results.spec.ts > Mixed Results > Test 4 - Should fail > chromium\nFILE: /Users/boyd/wip/reporters/typescript/playwright-reporter/tests/mixed-results.spec.ts:18\nTYPE: Type Error\n\nCODE CONTEXT:\n  16 |   test('Test 4 - Should fail', async () => {\n  17 |     const obj: any = undefined;\n> 18 |     expect(obj.property).toBe('value'); // Will fail: Cannot read property of undefined\n     |                ^\n  19 |   });\n  20 | \n\nFAILURE REASON: Type error: TypeError: Cannot read properties of undefined (reading 'property')\nFIX HINT: Check variable types and ensure proper initialization\n\n---",
        "test_failure_#2": "## TEST FAILURE #2",
        "test_failure_#3": "## TEST FAILURE #3",
        "test_failure_#4": "## TEST FAILURE #4",
        "test_failure_#5": "## TEST FAILURE #5",
        "error_patterns_detected": "## ERROR PATTERNS DETECTED\n- 5 tests failed due to Multiple failures in tests module\n- 3 tests failed due to Multiple assertion failures\n- 2 tests failed due to Multiple type-related errors\n\n---",
        "summary": "## SUMMARY\n- TOTAL TESTS: 11 (2 passed, 5 failed)\n- FAILURE RATE: 45.45%\n- DURATION: 1.77s\n- EXIT CODE: 1"
      }
    },
    "typescript_vitest_summary.txt": {
      "valid": true,
      "errors": [],
      "warnings": [],
      "sections": {
        "header": "# LLM TEST REPORTER - SUMMARY MODE\n",
        "suites": "SUITE: /Users/boyd/wip/reporters/typescript/vitest-reporter/tests/all-failing.test.ts\nFAILED TESTS:\n- Test 1 - Should fail: expected 'actual' to be 'expected' // Object.is equality\n- Test 2 - Should fail: Cannot read properties of null (reading 'length')\n- Test 3 - Should fail: Test timed out in 500ms.\n\n---\nSUITE: /Users/boyd/wip/reporters/typescript/vitest-reporter/tests/mixed-results.test.ts\nFAILED TESTS:\n- Test 2 - Should fail: expected 4 to be 5 // Object.is equality\n- Test 4 - Should fail: Cannot read properties of undefined (reading 'property')\n\n---",
        "summary": "## SUMMARY\n- PASSED SUITES: 0\n- FAILED SUITES: 2\n- TOTAL TESTS: 7 (2 passed, 5 failed)\n- DURATION: 0.68s\n- EXIT CODE: 1"
      }
    },
    "typescript_mocha_detailed.txt": {
      "valid": true,
      "errors": [],
      "warnings": [],
      "sections": {
        "header": "# LLM TEST REPORTER - DETAILED MODE\n",
        "test_failure_#1": "## TEST FAILURE #1",
        "suites": "SUITE: Mixed Results\nTEST: Mixed Results > Test 4 - Should fail\nFILE: /Users/boyd/wip/reporters/typescript/mocha-reporter/tests/mixed-results.test.js:1\nTYPE: Type Error\n\nCODE CONTEXT:\n> 1 | const assert = require('assert');\n  2 | \n  3 | describe('Mixed Results', function() {\n\nFAILURE REASON: Type error: Cannot read properties of undefined (reading 'property')\nFIX HINT: Check variable types and ensure proper initialization\n\n---",
        "test_failure_#2": "## TEST FAILURE #2",
        "test_failure_#3": "## TEST FAILURE #3",
        "test_failure_#4": "## TEST FAILURE #4",
        "test_failure_#5": "## TEST FAILURE #5",
        "error_patterns_detected": "## ERROR PATTERNS DETECTED\n- 5 tests failed due to Multiple failures in tests module\n- 2 tests failed due to Multiple assertion failures\n- 2 tests failed due to Multiple type-related errors\n\n---",
        "summary": "## SUMMARY\n- TOTAL TESTS: 8 (2 passed, 5 failed)\n- FAILURE RATE: 62.50%\n- DURATION: 0.51s\n- EXIT CODE: 1"
      }
    },
    "typescript_cypress_summary.txt": {
      "valid": true,
      "errors": [],
      "warnings": [
        "Excessive output before reporter: 8 lines (threshold: 5)"
      ],
      "sections": {
        "header": "# LLM TEST REPORTER - SUMMARY MODE\n",
        "suites": "SUITE: cypress/e2e/all-failing.cy.ts\nFAILED TESTS:\n- Test 1 - Should fail: expected 'actual' to equal 'expected'\n- Test 2 - Should fail: Cannot read properties of null (reading 'length')\n\n---\nSUITE: cypress/e2e/mixed-results.cy.ts\nFAILED TESTS:\n- Test 2 - Should fail: expected 4 to equal 5\n- Test 4 - Should fail: Cannot read properties of undefined (reading 'property')\n\n---",
        "summary": "## SUMMARY\n- PASSED SUITES: 1\n- FAILED SUITES: 2\n- TOTAL TESTS: 11 (6 passed, 4 failed)\n- DURATION: 0.00s\n- EXIT CODE: 1"
      }
    },
    "typescript_jest_summary.txt": {
      "valid": true,
      "errors": [],
      "warnings": [],
      "sections": {
        "header": "# LLM TEST REPORTER - SUMMARY MODE\n",
        "suites": "SUITE: /Users/boyd/wip/reporters/typescript/jest-reporter/tests/all-failing.test.ts\nFAILED TESTS:\n- All Failing Tests > Test 1 - Should fail: expect(received).toBe(expected) // Object.is equality\n- All Failing Tests > Test 2 - Should fail: Cannot read properties of null (reading 'length')\n- All Failing Tests > Test 3 - Should fail: thrown: \"Exceeded timeout of 500 ms for a test.\n\n---\nSUITE: /Users/boyd/wip/reporters/typescript/jest-reporter/tests/mixed-results.test.ts\nFAILED TESTS:\n- Mixed Results > Test 2 - Should fail: expect(received).toBe(expected) // Object.is equality\n- Mixed Results > Test 4 - Should fail: Cannot read properties of undefined (reading 'property')\n\n---",
        "summary": "## SUMMARY\n- PASSED SUITES: 1\n- FAILED SUITES: 2\n- TOTAL TESTS: 11 (5 passed, 5 failed)\n- DURATION: 1.96s\n- EXIT CODE: 1"
      }
    },
    "typescript_cypress_detailed.txt": {
      "valid": true,
      "errors": [],
      "warnings": [
        "Excessive output before reporter: 8 lines (threshold: 5)"
      ],
      "sections": {
        "header": "# LLM TEST REPORTER - DETAILED MODE\n",
        "test_failure_#1": "## TEST FAILURE #1",
        "suites": "SUITE: cypress/e2e/mixed-results.cy.ts\nTEST: Test 4 - Should fail\nFILE: cypress/e2e/mixed-results.cy.ts:12\nTYPE: Type Error\n\nCODE CONTEXT:\n  10 |   it('Test 3 - Should pass', () => {\n  11 |     expect(['apple', 'banana']).to.include('apple');\n> 12 |   });\n     |^\n  13 | \n  14 |   it('Test 4 - Should fail', () => {\n\nFAILURE REASON: Type error: Cannot read properties of undefined (reading 'property')\nFIX HINT: Check variable types and ensure proper initialization\n\n---",
        "test_failure_#2": "## TEST FAILURE #2",
        "test_failure_#3": "## TEST FAILURE #3",
        "test_failure_#4": "## TEST FAILURE #4",
        "error_patterns_detected": "## ERROR PATTERNS DETECTED\n- 4 tests failed due to Multiple failures in unknown module\n- 2 tests failed due to Multiple assertion failures\n- 2 tests failed due to Multiple type-related errors\n\n---",
        "summary": "## SUMMARY\n- TOTAL TESTS: 11 (6 passed, 4 failed)\n- FAILURE RATE: 36.36%\n- DURATION: 0.00s\n- EXIT CODE: 1"
      }
    },
    "python_pytest_summary.txt": {
      "valid": true,
      "errors": [],
      "warnings": [
        "Excessive output after reporter: 247 lines (threshold: 4)"
      ],
      "sections": {
        "header": "# LLM TEST REPORTER - SUMMARY MODE\n\nFFFFFFFF.FFFFFFFFFFFFF...................F.Fs.Fx..F..F.F..F.F.F          [100%]SUITE: /Users/boyd/wip/reporters/python/pytest-reporter/tests/test_all_failing.py\nFAILED TESTS:\n- tests/test_all_failing.py > TestAllFailures > test_assertion_failure: AssertionError: Expected 10 but got 5\nassert 5 == 10\n- tests/test_all_failing.py > TestAllFailures > test_type_mismatch: TypeError: can only concatenate str (not \"int\") to str\n- tests/test_all_failing.py > TestAllFailures > test_zero_division: ZeroDivisionError: division by zero\n- tests/test_all_failing.py > TestAllFailures > test_index_out_of_bounds: IndexError: list index out of range\n- tests/test_all_failing.py > TestAllFailures > test_key_not_found: KeyError: 'city'\n- tests/test_all_failing.py > TestAllFailures > test_attribute_missing: AttributeError: 'Person' object has no attribute 'age'\n- tests/test_all_failing.py > TestAllFailures > test_import_failure: ModuleNotFoundError: No module named 'non_existent_module'\n- tests/test_all_failing.py > TestAllFailures > test_value_conversion_error: ValueError: invalid literal for int() with base 10: 'not a number'\n- tests/test_all_failing.py > TestAllFailures > test_name_undefined: NameError: name 'undefined_variable' is not defined\n- tests/test_all_failing.py > TestComplexFailures > test_nested_assertion_failure: AssertionError: assert {'user': {'na...e': 'light'}}} == {'user': {'na...me': 'dark'}}}\n  \n  Differi...\n- tests/test_all_failing.py > TestComplexFailures > test_list_comparison_failure: assert [1, 2, 30, 40, 5] == [1, 2, 3, 4, 5]\n  \n  At index 2 diff: 30 != 3\n  Use -v to get more diff\n- tests/test_all_failing.py > TestComplexFailures > test_custom_exception: test_all_failing.TestComplexFailures.test_custom_exception.<locals>.CustomError: Operation failed du...\n- tests/test_all_failing.py > TestComplexFailures > test_multiple_assertions_fail: assert 5 > 10\n- tests/test_all_failing.py > test_parametrized_all_fail[1-2]: assert 1 == 2\n- tests/test_all_failing.py > test_parametrized_all_fail[2-3]: assert 2 == 3\n- tests/test_all_failing.py > test_parametrized_all_fail[3-5]: assert 3 == 5\n- tests/test_all_failing.py > test_parametrized_all_fail[4-7]: assert 4 == 7\n- tests/test_all_failing.py > TestAsyncFailures > test_async_assertion_failure: assert 42 == 100\n- tests/test_all_failing.py > TestAsyncFailures > test_async_exception: RuntimeError: Async operation failed\n- tests/test_all_failing.py > test_fixture_usage_failure: assert 1 == 2\n- tests/test_all_failing.py > test_permission_denied: FileNotFoundError: [Errno 2] No such file or directory: '/root/test.txt'\n",
        "suites": "SUITE: /Users/boyd/wip/reporters/python/pytest-reporter/tests/test_mixed_results.py\nFAILED TESTS:\n- tests/test_mixed_results.py > TestMixedResults > test_failing_equality: assert 4 == 5\n- tests/test_mixed_results.py > TestMixedResults > test_failing_type_error: TypeError: can only concatenate str (not \"int\") to str\n- tests/test_mixed_results.py > TestMixedResults > test_failing_key_error: KeyError: 'city'\n- tests/test_mixed_results.py > TestAsyncOperations > test_async_timeout: TimeoutError\n- tests/test_mixed_results.py > TestParametrizedMixed > test_square_numbers[4-15]: assert (4 ** 2) == 15\n- tests/test_mixed_results.py > TestParametrizedMixed > test_square_numbers[6-35]: assert (6 ** 2) == 35\n- tests/test_mixed_results.py > TestParametrizedMixed > test_string_length[python-7]: AssertionError: assert 6 == 7\n +  where 6 = len('python')\n- tests/test_mixed_results.py > TestParametrizedMixed > test_string_length[test-5]: AssertionError: assert 4 == 5\n +  where 4 = len('test')\n- tests/test_mixed_results.py > test_value_error_handling: ValueError: invalid literal for int() with base 10: 'not a number'\n\n---",
        "summary": "## SUMMARY\n- PASSED SUITES: 1\n- FAILED SUITES: 2\n- TOTAL TESTS: 62 (31 passed, 30 failed, 1 skipped)\n- DURATION: 10.21s\n- EXIT CODE: 1\n\n=================================== FAILURES ===================================\n____________________ TestAllFailures.test_assertion_failure ____________________\ntests/test_all_failing.py:15: in test_assertion_failure\n    assert actual == expected, f\"Expected {expected} but got {actual}\"\nE   AssertionError: Expected 10 but got 5\nE   assert 5 == 10\n______________________ TestAllFailures.test_type_mismatch ______________________\ntests/test_all_failing.py:20: in test_type_mismatch\n    result = \"string\" + 123\n             ^^^^^^^^^^^^^^\nE   TypeError: can only concatenate str (not \"int\") to str\n______________________ TestAllFailures.test_zero_division ______________________\ntests/test_all_failing.py:27: in test_zero_division\n    result = numerator / denominator\n             ^^^^^^^^^^^^^^^^^^^^^^^\nE   ZeroDivisionError: division by zero\n___________________ TestAllFailures.test_index_out_of_bounds ___________________\ntests/test_all_failing.py:34: in test_index_out_of_bounds\n    value = items[10]\n            ^^^^^^^^^\nE   IndexError: list index out of range\n______________________ TestAllFailures.test_key_not_found ______________________\ntests/test_all_failing.py:41: in test_key_not_found\n    city = data[\"city\"]\n           ^^^^^^^^^^^^\nE   KeyError: 'city'\n____________________ TestAllFailures.test_attribute_missing ____________________\ntests/test_all_failing.py:52: in test_attribute_missing\n    age = person.age\n          ^^^^^^^^^^\nE   AttributeError: 'Person' object has no attribute 'age'\n_____________________ TestAllFailures.test_import_failure ______________________\ntests/test_all_failing.py:57: in test_import_failure\n    import non_existent_module\nE   ModuleNotFoundError: No module named 'non_existent_module'\n_________________ TestAllFailures.test_value_conversion_error __________________\ntests/test_all_failing.py:63: in test_value_conversion_error\n    number = int(text)\n             ^^^^^^^^^\nE   ValueError: invalid literal for int() with base 10: 'not a number'\n_____________________ TestAllFailures.test_name_undefined ______________________\ntests/test_all_failing.py:75: in test_name_undefined\n    result = undefined_variable * 2\n             ^^^^^^^^^^^^^^^^^^\nE   NameError: name 'undefined_variable' is not defined\n______________ TestComplexFailures.test_nested_assertion_failure _______________\ntests/test_all_failing.py:104: in test_nested_assertion_failure\n    assert actual == expected\nE   AssertionError: assert {'user': {'na...e': 'light'}}} == {'user': {'na...me': 'dark'}}}\nE     \nE     Differing items:\nE     {'user': {'name': 'John', 'settings': {'notifications': False, 'theme': 'light'}}} != {'user': {'name': 'John', 'settings': {'notifications': True, 'theme': 'dark'}}}\nE     Use -v to get more diff\n_______________ TestComplexFailures.test_list_comparison_failure _______________\ntests/test_all_failing.py:110: in test_list_comparison_failure\n    assert actual == expected\nE   assert [1, 2, 30, 40, 5] == [1, 2, 3, 4, 5]\nE     \nE     At index 2 diff: 30 != 3\nE     Use -v to get more diff\n__________________ TestComplexFailures.test_custom_exception ___________________\ntests/test_all_failing.py:120: in test_custom_exception\n    result = risky_operation()\n             ^^^^^^^^^^^^^^^^^\ntests/test_all_failing.py:118: in risky_operation\n    raise CustomError(\"Operation failed due to custom reason\")\nE   test_all_failing.TestComplexFailures.test_custom_exception.<locals>.CustomError: Operation failed due to custom reason\n______________ TestComplexFailures.test_multiple_assertions_fail _______________\ntests/test_all_failing.py:126: in test_multiple_assertions_fail\n    assert value > 10  # This fails\n    ^^^^^^^^^^^^^^^^^\nE   assert 5 > 10\n_______________________ test_parametrized_all_fail[1-2] ________________________\ntests/test_all_failing.py:139: in test_parametrized_all_fail\n    assert input == expected\nE   assert 1 == 2\n_______________________ test_parametrized_all_fail[2-3] ________________________\ntests/test_all_failing.py:139: in test_parametrized_all_fail\n    assert input == expected\nE   assert 2 == 3\n_______________________ test_parametrized_all_fail[3-5] ________________________\ntests/test_all_failing.py:139: in test_parametrized_all_fail\n    assert input == expected\nE   assert 3 == 5\n_______________________ test_parametrized_all_fail[4-7] ________________________\ntests/test_all_failing.py:139: in test_parametrized_all_fail\n    assert input == expected\nE   assert 4 == 7\n________________ TestAsyncFailures.test_async_assertion_failure ________________\ntests/test_all_failing.py:152: in test_async_assertion_failure\n    assert result == 100\nE   assert 42 == 100\n____________________ TestAsyncFailures.test_async_exception ____________________\ntests/test_all_failing.py:160: in test_async_exception\n    result = await failing_operation()\n             ^^^^^^^^^^^^^^^^^^^^^^^^^\ntests/test_all_failing.py:158: in failing_operation\n    raise RuntimeError(\"Async operation failed\")\nE   RuntimeError: Async operation failed\n__________________________ test_fixture_usage_failure __________________________\ntests/test_all_failing.py:177: in test_fixture_usage_failure\n    assert data[\"count\"] == 2\nE   assert 1 == 2\n____________________________ test_permission_denied ____________________________\ntests/test_all_failing.py:183: in test_permission_denied\n    with open(\"/root/test.txt\", \"w\") as f:\n         ^^^^^^^^^^^^^^^^^^^^^^^^^^^\nE   FileNotFoundError: [Errno 2] No such file or directory: '/root/test.txt'\n____________________ TestMixedResults.test_failing_equality ____________________\ntests/test_mixed_results.py:20: in test_failing_equality\n    assert result == 5  # This will fail\n    ^^^^^^^^^^^^^^^^^^\nE   assert 4 == 5\n___________________ TestMixedResults.test_failing_type_error ___________________\ntests/test_mixed_results.py:31: in test_failing_type_error\n    result = \"string\" + 5\n             ^^^^^^^^^^^^\nE   TypeError: can only concatenate str (not \"int\") to str\n___________________ TestMixedResults.test_failing_key_error ____________________\ntests/test_mixed_results.py:50: in test_failing_key_error\n    value = data[\"city\"]\n            ^^^^^^^^^^^^\nE   KeyError: 'city'\n____________________ TestAsyncOperations.test_async_timeout ____________________\ntests/test_mixed_results.py:82: in slow_operation\n    await asyncio.sleep(10)  # This will timeout\n    ^^^^^^^^^^^^^^^^^^^^^^^\n/opt/homebrew/Cellar/python@3.13/3.13.3_1/Frameworks/Python.framework/Versions/3.13/lib/python3.13/asyncio/tasks.py:718: in sleep\n    return await future\n           ^^^^^^^^^^^^\nE   asyncio.exceptions.CancelledError\n\nThe above exception was the direct cause of the following exception:\ntests/test_mixed_results.py:86: in test_async_timeout\n    result = await asyncio.wait_for(slow_operation(), timeout=0.1)\n             ^^^^^^^^^^^^^^^^^^^^^^^^^^^^^^^^^^^^^^^^^^^^^^^^^^^^^\n/opt/homebrew/Cellar/python@3.13/3.13.3_1/Frameworks/Python.framework/Versions/3.13/lib/python3.13/asyncio/tasks.py:506: in wait_for\n    async with timeouts.timeout(timeout):\n               ^^^^^^^^^^^^^^^^^^^^^^^^^\n/opt/homebrew/Cellar/python@3.13/3.13.3_1/Frameworks/Python.framework/Versions/3.13/lib/python3.13/asyncio/timeouts.py:116: in __aexit__\n    raise TimeoutError from exc_val\nE   TimeoutError\n_______________ TestParametrizedMixed.test_square_numbers[4-15] ________________\ntests/test_mixed_results.py:102: in test_square_numbers\n    assert value ** 2 == expected\nE   assert (4 ** 2) == 15\n_______________ TestParametrizedMixed.test_square_numbers[6-35] ________________\ntests/test_mixed_results.py:102: in test_square_numbers\n    assert value ** 2 == expected\nE   assert (6 ** 2) == 35\n______________ TestParametrizedMixed.test_string_length[python-7] ______________\ntests/test_mixed_results.py:113: in test_string_length\n    assert len(text) == length\nE   AssertionError: assert 6 == 7\nE    +  where 6 = len('python')\n_______________ TestParametrizedMixed.test_string_length[test-5] _______________\ntests/test_mixed_results.py:113: in test_string_length\n    assert len(text) == length\nE   AssertionError: assert 4 == 5\nE    +  where 4 = len('test')\n__________________________ test_value_error_handling ___________________________\ntests/test_mixed_results.py:137: in test_value_error_handling\n    result = parse_number(\"not a number\")\n             ^^^^^^^^^^^^^^^^^^^^^^^^^^^^\ntests/test_mixed_results.py:134: in parse_number\n    return int(text)\n           ^^^^^^^^^\nE   ValueError: invalid literal for int() with base 10: 'not a number'\nTraceback (most recent call last):\n  File \"/Users/boyd/wip/reporters/python/.venv/bin/pytest\", line 8, in <module>\n    sys.exit(console_main())\n             ~~~~~~~~~~~~^^\n  File \"/Users/boyd/wip/reporters/python/.venv/lib/python3.13/site-packages/_pytest/config/__init__.py\", line 201, in console_main\n    code = main()\n  File \"/Users/boyd/wip/reporters/python/.venv/lib/python3.13/site-packages/_pytest/config/__init__.py\", line 175, in main\n    ret: ExitCode | int = config.hook.pytest_cmdline_main(config=config)\n                          ~~~~~~~~~~~~~~~~~~~~~~~~~~~~~~~^^^^^^^^^^^^^^^\n  File \"/Users/boyd/wip/reporters/python/.venv/lib/python3.13/site-packages/pluggy/_hooks.py\", line 512, in __call__\n    return self._hookexec(self.name, self._hookimpls.copy(), kwargs, firstresult)\n           ~~~~~~~~~~~~~~^^^^^^^^^^^^^^^^^^^^^^^^^^^^^^^^^^^^^^^^^^^^^^^^^^^^^^^^\n  File \"/Users/boyd/wip/reporters/python/.venv/lib/python3.13/site-packages/pluggy/_manager.py\", line 120, in _hookexec\n    return self._inner_hookexec(hook_name, methods, kwargs, firstresult)\n           ~~~~~~~~~~~~~~~~~~~~^^^^^^^^^^^^^^^^^^^^^^^^^^^^^^^^^^^^^^^^^\n  File \"/Users/boyd/wip/reporters/python/.venv/lib/python3.13/site-packages/pluggy/_callers.py\", line 167, in _multicall\n    raise exception\n  File \"/Users/boyd/wip/reporters/python/.venv/lib/python3.13/site-packages/pluggy/_callers.py\", line 121, in _multicall\n    res = hook_impl.function(*args)\n  File \"/Users/boyd/wip/reporters/python/.venv/lib/python3.13/site-packages/_pytest/main.py\", line 336, in pytest_cmdline_main\n    return wrap_session(config, _main)\n  File \"/Users/boyd/wip/reporters/python/.venv/lib/python3.13/site-packages/_pytest/main.py\", line 324, in wrap_session\n    config.hook.pytest_sessionfinish(\n    ~~~~~~~~~~~~~~~~~~~~~~~~~~~~~~~~^\n        session=session, exitstatus=session.exitstatus\n        ^^^^^^^^^^^^^^^^^^^^^^^^^^^^^^^^^^^^^^^^^^^^^^\n    )\n    ^\n  File \"/Users/boyd/wip/reporters/python/.venv/lib/python3.13/site-packages/pluggy/_hooks.py\", line 512, in __call__\n    return self._hookexec(self.name, self._hookimpls.copy(), kwargs, firstresult)\n           ~~~~~~~~~~~~~~^^^^^^^^^^^^^^^^^^^^^^^^^^^^^^^^^^^^^^^^^^^^^^^^^^^^^^^^\n  File \"/Users/boyd/wip/reporters/python/.venv/lib/python3.13/site-packages/pluggy/_manager.py\", line 120, in _hookexec\n    return self._inner_hookexec(hook_name, methods, kwargs, firstresult)\n           ~~~~~~~~~~~~~~~~~~~~^^^^^^^^^^^^^^^^^^^^^^^^^^^^^^^^^^^^^^^^^\n  File \"/Users/boyd/wip/reporters/python/.venv/lib/python3.13/site-packages/pluggy/_callers.py\", line 167, in _multicall\n    raise exception\n  File \"/Users/boyd/wip/reporters/python/.venv/lib/python3.13/site-packages/pluggy/_callers.py\", line 139, in _multicall\n    teardown.throw(exception)\n    ~~~~~~~~~~~~~~^^^^^^^^^^^\n  File \"/Users/boyd/wip/reporters/python/.venv/lib/python3.13/site-packages/_pytest/logging.py\", line 873, in pytest_sessionfinish\n    return (yield)\n            ^^^^^\n  File \"/Users/boyd/wip/reporters/python/.venv/lib/python3.13/site-packages/pluggy/_callers.py\", line 152, in _multicall\n    teardown.send(result)\n    ~~~~~~~~~~~~~^^^^^^^^\n  File \"/Users/boyd/wip/reporters/python/.venv/lib/python3.13/site-packages/_pytest/terminal.py\", line 944, in pytest_sessionfinish\n    self.config.hook.pytest_terminal_summary(\n    ~~~~~~~~~~~~~~~~~~~~~~~~~~~~~~~~~~~~~~~~^\n        terminalreporter=self, exitstatus=exitstatus, config=self.config\n        ^^^^^^^^^^^^^^^^^^^^^^^^^^^^^^^^^^^^^^^^^^^^^^^^^^^^^^^^^^^^^^^^\n    )\n    ^\n  File \"/Users/boyd/wip/reporters/python/.venv/lib/python3.13/site-packages/pluggy/_hooks.py\", line 512, in __call__\n    return self._hookexec(self.name, self._hookimpls.copy(), kwargs, firstresult)\n           ~~~~~~~~~~~~~~^^^^^^^^^^^^^^^^^^^^^^^^^^^^^^^^^^^^^^^^^^^^^^^^^^^^^^^^\n  File \"/Users/boyd/wip/reporters/python/.venv/lib/python3.13/site-packages/pluggy/_manager.py\", line 120, in _hookexec\n    return self._inner_hookexec(hook_name, methods, kwargs, firstresult)\n           ~~~~~~~~~~~~~~~~~~~~^^^^^^^^^^^^^^^^^^^^^^^^^^^^^^^^^^^^^^^^^\n  File \"/Users/boyd/wip/reporters/python/.venv/lib/python3.13/site-packages/pluggy/_callers.py\", line 167, in _multicall\n    raise exception\n  File \"/Users/boyd/wip/reporters/python/.venv/lib/python3.13/site-packages/pluggy/_callers.py\", line 139, in _multicall\n    teardown.throw(exception)\n    ~~~~~~~~~~~~~~^^^^^^^^^^^\n  File \"/Users/boyd/wip/reporters/python/.venv/lib/python3.13/site-packages/_pytest/terminal.py\", line 966, in pytest_terminal_summary\n    return (yield)\n            ^^^^^\n  File \"/Users/boyd/wip/reporters/python/.venv/lib/python3.13/site-packages/pluggy/_callers.py\", line 139, in _multicall\n    teardown.throw(exception)\n    ~~~~~~~~~~~~~~^^^^^^^^^^^\n  File \"/Users/boyd/wip/reporters/python/.venv/lib/python3.13/site-packages/_pytest/warnings.py\", line 110, in pytest_terminal_summary\n    return (yield)\n            ^^^^^\n  File \"/Users/boyd/wip/reporters/python/.venv/lib/python3.13/site-packages/pluggy/_callers.py\", line 121, in _multicall\n    res = hook_impl.function(*args)\n  File \"/Users/boyd/wip/reporters/python/pytest-reporter/src/llm_pytest_reporter/plugin.py\", line 199, in pytest_terminal_summary\n    terminalreporter._durations.clear()\n    ^^^^^^^^^^^^^^^^^^^^^^^^^^^\nAttributeError: 'TerminalReporter' object has no attribute '_durations'\n"
      }
    },
    "typescript_jest_detailed.txt": {
      "valid": true,
      "errors": [],
      "warnings": [
        "Excessive output before reporter: 6 lines (threshold: 5)"
      ],
      "sections": {
        "header": "# LLM TEST REPORTER - DETAILED MODE\n",
        "test_failure_#1": "## TEST FAILURE #1",
        "suites": "SUITE: mixed-results\nTEST: Mixed Results > Test 4 - Should fail\nFILE: /Users/boyd/wip/reporters/typescript/jest-reporter/tests/mixed-results.test.ts:18\nTYPE: Type Error\n\nCODE CONTEXT:\n  16 |   test('Test 4 - Should fail', () => {\n  17 |     const obj: any = undefined;\n> 18 |     expect(obj.property).toBe('value'); // Will fail: Cannot read property of undefined\n     |                ^\n  19 |   });\n  20 | \n\nFAILURE REASON: Type error: Cannot read properties of undefined (reading 'property')\nFIX HINT: Check variable types and ensure proper initialization\n\n---",
        "test_failure_#2": "## TEST FAILURE #2",
        "test_failure_#3": "## TEST FAILURE #3",
        "test_failure_#4": "## TEST FAILURE #4",
        "test_failure_#5": "## TEST FAILURE #5",
        "error_patterns_detected": "## ERROR PATTERNS DETECTED\n- 5 tests failed due to Multiple failures in tests module\n- 3 tests failed due to Multiple assertion failures\n- 2 tests failed due to Multiple type-related errors\n- 2 tests failed due to Multiple expectation mismatches\n\n---",
        "summary": "## SUMMARY\n- TOTAL TESTS: 11 (5 passed, 5 failed)\n- FAILURE RATE: 45.45%\n- DURATION: 1.88s\n- EXIT CODE: 1"
      }
    }
  }
}